Workbook

Sheet ConsolidatedMHrequirementApr25
A1: Consolidated man hour requirement for Apr'25
A2: =(20*8*6)
A3: Job No | B3: No. of orders | C3: Exp. | D3: Inspn | E3: Others | F3: Total | G3: *Others/ Remarks | J3: Insp/ Project Coordinators | N3: MH available as on | O3: MH to be released for Apr'25 | P3: Allotted | Q3: 8518 reqd
A4: B016 | B4: 0 | C4: 0 | E4: 0 | F4: 0 | J4: Uday Pratap Singh/Pankaj Saxena/Alok Singh | Q4: 10h issued on 2/5[1714];16h rel on 2/7[1722];8h rel on 12/9[1730] for VFD
A5: B035 | B5: 1 | C5: =1*8 | D5: 0 | E5: 0 | F5: =C5+D5+E5 | G5: Expediting - Greensol; | J5: Saeed Akhtar/ D Jana | N5: 0 | O5: =F5-N5 | Q5: 47 hr avl on 19/7;64 h already bkd in jul; 28 hrs relsd on 16/11;24h relsd on 18/12;24h relsd on 14/1;32h issued-RAM val extn for YVT reqd;16 h on 16/3/20;16h relsd on 23/6/20; J/F/M request:80/40/40; 96 hrs given on 4/2/21'40h on 30/3/21;16h allotted on 28/6;40h relsd on 25/8;24h relsd on 26/10;32h relsd on25/11;24 h rel. in Dec;24h rel on 3/2/22;8h relsd on 1/8/22;8h relsd on 29/8;32h rel on 27/9;8h rel on 10/1[1249];8h on 9/2[1257];8h on 1/5[1275];8h on 31/5[1283];8h on 28/7[1291];8 h on 15/9[1307];8 h on 26/9[1315];32h rel on 1/12[1407;32h rel on 8/1[1471]; 8h+ 4h(B302) rel on 12/2[1483];8h +6h(B302) rel on 11/3[1497];8h rel on 1/4[1505];8h rel on 13/5[1513];16h for May & Jun rel on 1/7[1539];8h rel on 9/8[1555] 90h rel on 12/10 [1645]-10h bal c/f to Oct;8h rel on 28/2[1653]
A6: B038 | B6: 2 | C6: =2*2 | D6: 0 | E6: 0 | F6: =C6+D6+E6 | G6: Expediting/fin.doc subm followup & OCS prep(16 nos) - 24h sought for Time ex.of YIL & other activities of past for CPCL on 22/12/21 - 16h relsd on 31/12/21; 1 Ord on FS recd in Oct-4h rel on 28/10; 8h sought on 5/12; Dec: 2 OCS +5 run. Ord. expediting - 28h sought (8h rel); Jan: 5 run ord +2 FD exp,Sandvik Mtgs - 36h sought - 12h rel [32];FEb- 20h sought-none relsd; Mar:32h sought- 16h issued; Meeting at Sandvik on 11/4/23 with MRPL; Apr:5 running orders+3FD expediting(32h)- total:40h sought - May: Alliema VC on 16/5/23;5 running orders+3FD expediting(32h)- 40h sought; 6r orders+2 OCS+Alliema expediting - 40h sought in Jun-16 relsd.[120];40 sought in Jul(8 ord+Alleima- exp incl. mtg on 26/7)); 36h sought in Aug- incl.7 orders(4 running) & Alleima Expediting [64 h sought on 28/8 incl. 28h short of Jul]; [20 h relsd [168] ;6 orders expediting- 24h;6 orders expediting;1 OCS on 12/9;Alleima expediting including visits to Hosur works on 1 & 7/9;Oct: 1 OCS done(704), 5 orders expediting- sought 24h;Nov: 7ord exp- 14hrs sought; Dec: 7 order expediting - 14h +4h- mtg with Head of Swims& IL for urgent intervention; Jan:7 ord exp - 14h(not rel); Feb:2Runn ord exp +1OCS+4FD exp; Mar: 2 Runn ord+3FDsub exp+1 OCS; Mtg with YIL on 7/3/24 for Turnkey Instn Job;Apr: 1 Rord;3 FD exp+1OCS;mtg with YIL -29/4; May: 2 FD exp+1OCS+ 1Rord Exp -8h;Jun: 1FD exp+1OCS+1Rord Exp-6h; Jul: 1ord fd exp; 1ord- YIL - excl.exp. with mtgs & daily f/ups; Aug- 2 ord - 4h; Sep-2 ord FD - 4h; Oct-2ord FD-4h ;Nov-2ord FD-4h;Dec-2ord FD-4h;Jan,Feb,Mar-2ord FD-4h; Apr- 2ord (incl 1OCS) -4h | J6: Himanghsu Pal/Sanjeev Kumar/Aasheesh Handa | N6: 0 | O6: =F6-N6 | Q6: 60 hr allocated on 22/2/19 (first time); 140 hrs allotted on 26/4/19; 200h relsd on 7/8/19; 40 hrs relsd on 5/11/19;50 hrs relsd on 13/1/20;40 hr relsd on 20/2;;Bal. MH reqd from May'20 till completion of activities: 8 orders - 3 orders can get completed by Jul'20; bal 5 orders will go upto Sept- so Exp:3*3*4+5*5*4=136hrs;FD/OCS-29 orders -29*4*3=348 - So total - 484 mh; 16 hrs avl as on 27/5/20; 20 hrs avl. as on 20/8- RAM auth to be chkd;130h allotted on 29/9 - till end of pjt -brk up 40(sep),40(oct),50(Nov);16h relsd on 31/12/21;8h rel on 12/12; 8h rel on 6/1/23;12mh rel on 17/2 against 36 sought[32] b038-02;16h ag.20hsought on 27/2[48]; 16h rel on 6/4 against 20 sought[64];22h given against 40 sought on 15/5/23 [88];16h given in place of 40 on 19/6[104];12h (in place of 40h) rel on 8/8[132];28h rel on 7/9[160];16h rel on 9/10-sep ts closed - so used for Oct[184];26h rel on 18/12[210];10h on 11/1[220];7h rel on 4/3/24[234];16h rel for Mar [250];;8h on 4/6[270]8h rel on 4/8[278]
A7: B058 | B7: 1 | C7: 0 | F7: 0 | J7: Patra/Sanjay Dhuria | Q7: 8h rel on 1/8
A8: B224 -03 | B8: CDU/VDU | C8: Tata Projects | F8: 0 | J8: Mr Dipak Panchal / Mr Sunil Saurabh/ Mr R.K.Mohabe/Neena Mukherjee | N8: 0 | O8: 56 | Q8: 20 hrs issued on 9/20- addl 48 hrs provided on 18/11/20;48h recd on 8/1/21;64 mh against B224-05 recd on 14/5/21;56 h on 1/6/21;140h relsd on 6/12/21;190h relsd on 28/12/21;112h relsd on 2/2/22;64h relsd on 28/2/22;216h relsd on 28/3/22;88h relsd on 4/5/22;80h relsd on 29/6/22;80h relsd on 1/8/22;316h against all units relsd on 28/9 in unit 00; 114h relsd on 3/11/22; 120 h relsd on 4/12 against req. of 212h(804 in Unit 00 as on 6/12); 300 rel. on 6/1 in place of 388 sought [1104];172h rel on 172 on 16/2[1276];256h rel on 7/3[1532];300h (against 360 sought) rel on 5/4[1832];304h rel on 12/5[2136];300mh rel on 31/5 against 408 sought [2436]; 200h rel on 9/8 (264 sought)[3039]; 440h sought on 28/8 & resld on 11/9; 372h sought on 26/9- relsd on 4/10; 301 hr rel. for Nov & Dec against 480 sought on 8/1/24[4482];240mh issued on22/2 (against 252 sought) [4735];150h rel on 1/4 for feb & 150h rel on 6/4 for mar[5035];96h rel on 21/5[5131];96h rel on 2/7/24 (for May'24)[5227];272h rel on 16/7[5499]; 40h rel on 12/10[5635];90h rel on 10/1[5720];100h rel on 20/1[5820];21h rel on 10/2[5841];307h rel for Jan-Mar on 24/4
A9: B224 -03 | B9: VGO | C9: Tata Projects | J9: Mr Aasheesh Handa / Mr Manoj Kumar/ Mr R.K.Mohabe
A10: B224 -03 | B10: DCU | C10: Tata Projects | F10: 0 | J10: Mr Arun Sharma / Mr Pawan Kumar Singh/ Mr R.K.Mohabe
A11: B224 -03 | B11: DHDT/ HGU | C11: TOYO | F11: 0 | J11: Ms Gauri Sharma / Mr K.Manish/Mr R.K. Mohabe/Neena | P11: 56 hrs relsd on 27/9 ;80h relsd against b224-00 on 11/8/22; 104 mh for 03 & 04 relsd on 9/9 against Unit-00;144h rel on 3/11;100h rel on 20/1 [5825]
A12: B224 -03 | B12: PFCCU | C12: L & T | F12: 0 | J12: Ms Tania Mukharjee / Mr Arunabh Bera/Mr R.K.Mohabe
A13: B224-04 | B13: DFCU | C13: L & T | F13: =8*0.5 | G13: Insp: L&T /YIL -Doc rev+IRN end-5/4(0.5d) | J13: Mr Sharad Saxena/ Mr Abhay Pratap Singh / Mr S.K.Singh/Sheesham | P13: Auth & MH rel pending- Sheesham!SV/NV- 144h issued on 28/3/22;56h relsd on 4/5/22;88h resld on 2/6/22;32h relsd on 6/7/22
A14: B224-04 | B14: Petrochemical | J14: Mr Navneet Mann / Mr Rakesh Sharma /Mr S.K.Singh
A15: B224-05 | B15: Offsites & Utilities | F15: =8*0.5 | G15: Inspn:Afcons/Emerson-UFM- Doc/Compliance rev - 2/4 (0.5d); | J15: Mr Raju Chutani/ Mr Gul Nebhanani | P15: 88mh resld on 30/12/21;136h relsd on 28/2/22;112 h relsd on 30/3/22;40h on 28/5/22;40h relsd on 1/7/22;24h rel on 29/8
A16: B224-06 | B16: SRU | C16: MEIL | E16: 0 | F16: =8*0.5 | G16: Koso Valve QAP appl (17/4 - 0.5d)
A17: B224-08 | B17: LLDPE | C17: MEIL | F17: =8*1 | G17: YIL - Shelters - Inlet Pump Skids Insp - 7/4 - (1d) | J17: Mr Nitin Deoras/ Maya Jagdev
A18: B224-09 | B18: PPU | C18: MEIL | F18: =8*2.5 | G18: Vertiv ACDB QAP-28/4 (0.5d);Motor- ABB Finland, Vertiv -ACDBs with Static switch - QAP appl - 4h; VSD- Hitachi,Korea; TPI doc. Rev. - 4hrs on 21 & 4h on 28/4 (1d);Schneider 6.6kV QAP appl -2/4-(0.5d) | J18: Mr Navneet Mann / Mr Rakesh Sharma /Mr S.K.Singh
A19: B224-10 | C19: MEIL | F19: 0
A20: B229 | B20: 3 | C20: =2*3+8 | E20: 0 | F20: =SUM(C20:E20) | G20: 1order FD f/up +2 OCS | J20: Patra/JPS Kalra/DK Kesri | Q20: 40 hrs relsd on 13/8/21; 16 hr to be relsd on 29/9;24 hrs relsd on 31/12;24h relsd on 8/2/22;24h relsd on 9/5/22'20h resld on 9/6/22;24h relsd on 15/7;228 consumed as on 1/8/22;20 h relsd on 2/8/22; 20h resld on 12/9/22;24h relsd on 3/10;10h rel on 9/12;28h rel on 9/1[345];48h rel on 14/3 for Jan/Feb [393];20h rel on 17/4[413];20h rel on 15/5[433];36h rel on 22/6[469];32h rel on 11/7[501];56 h sought for Jul(32)+Aug(24) on 28/8 - 32h of Jul rel. on 11/9[533];16h rel on 5/10[549];20h rel on 29/11[569];40h rel on 27/12[609];30h on 10/1[639];40h on 21/2[679];16h on 29/3[695];30h on 5/4[725];;16h rel on 16/5[741];-16h rel on 16/7[757]; 24 h rel on 12/10 but not utilised since Name appl. Not yet recd - to be c/f to Oct[765];10h rel on 10/12[775]; 100h rel on 23/1[883;8h rel on 6/3 [901]
A21: B269 | B21: 16 | C21: =2*16+4*2 | D21: =8*8 | E21: 0 | F21: =SUM(C21:E21) | G21: 11 running orders+ 3Orders FD sub expediting+2OCS; Critical Item Insp - YIL- RHCU FAT- 5d (28/4-2/5-(5d); FF Doc Rev/IRN endor - 26/4(1d);YIL -B269/1408 -Shelter-11/4(1d); Mtg with ABB at Office for review of orders - 10/4 (8h) | J21: Chandrashekhar/Rajesh Bhatla/Arun Singh Arya/Sanjay Chaudhary | N21: 0 | Q21: ;32h rel in place of 60h sought on 15/6[532];48h rel on 10/7 in pl. of 76 sought[580];36h (80 sought)rel on 8/8[640]; 49 h rel on ag. 88 sought on18/9 [689];96h rel on 4/10[785] ;42h rel on 29/11(for month of Oct)[827];30h rel on11/1 [857];80h rel on 18/1[937];40h rel on 19/2[977];24h rel against 50h sought on 13/3[1001];36h rel on 10/4[1037]-to be used in Apr since Mar TS already closed.;20mh rel on 2/7(for may)[1057];27h rel on 10/7[1084];40h rel on 9/8[1124]; 20h rel on 12/10[1174];48h rel on 30/12[1222];20mh rel on 8/1[1242];100h addl given on 20/1[1342];50h rel on 19/2[1392];30h rel on 19/3[1422];16mh rel on 17/4 [1438]
A22: B285 | J22: Sanjeev Kumar/Vikalp Paliwal
A23: B297 | B23: 7 | C23: =7*2+4 | D23: 8 | E23: 0 | F23: =SUM(C23:E23) | G23: Exp-6 ord-4 runn ord, 2-FD sub; 1OCS; Insp: B297/301 (4/4 - 1d) | J23: Chandrashekar/NS Vasudev/Manish Tiwari - GAIL Pata | N23: 10 | Q23: 24h allotted on 25/2/22;44 h allotted on 2/6/22(against 64 sought) - 60h bkd in Jun correspond to previous month; jun rel. not happened sought 88h for Jun/Jul [128 h as of 11/8/22]-80h issued on 22/8/22; 28h resld on 25/8; 232h as on 6/9/22;268 as on 28/10(32 h rel for Sep being util. in Oct);30mh rel on 11/11;40 h rel on 7/12(338 as on 7/12);40h issued on 11/1 [378];30mh issued in Feb 10h avl on 9/2[408];46h given on 9/3 in pl of 68 sought [454]; 100h rel on 6/6 for May'23[554];40 on 8/7 in pl. of 184 h sought[594];20h rel on 9/10- sep ts closed so used in Oct [614] 30h rel for Oct[644]; 32 h rel on 15/12 against 58 sought[676];24h rel on 12/3 ag. 58 sought[755];18h rel on 5/4[773];16h rel on 15/5[789];16h rel on 24/6 [805];32;8h rel on 11/3 [965]h rel on 12/7[837];24h rel on 12/8[861];20h rel on 10/9[881];16h rel on 14/10[897]; 24h rel on 19/11[921];16h rel on 10/12[937];20h rel on 13/1[957];8h rel on 17/3[965]
A24: B302 | B24: 4 | C24: =2*4+4*2 | D24: 0 | E24: 16 | F24: =SUM(C24:E24) | G24: 4 Running orders ; Shirdi Sai -Online mtg/QAP appls, KOM for Turnkey Inst. Job - YIL | J24: Suresh/D Jana(302-1)/Sivakumar(302-2)/Abhishek Rai/Balbir Singh (01-P/L & 02- COT) - pump order - 02; FOA also to incl. Unit no for correlation | Q24: 8hr allotted on 31/10/21;4h all. On 30/11;16h relsd on 6/2/22;56h relsd against B302-01 on 1/4/22;56h of Mar'22 of 02 unit relsd on 4/5/22;36h for Jul/Aug/Sep'23 relsd against B035 on 3/10;4h rel against B035 on 12/2;10h rel against B035 on 29/5[1523];106 mh rel against 6979 on 21/4 (for Jan/Feb/Mar) 6979-[202]
A25: B348 | B25: 14 | C25: =2*B25+2*2 | D25: 0 | E25: 0 | F25: =SUM(C25:E25) | G25: 12 Running orders +2 ord FD exp | J25: Himangshu/Sanjeev Kumar/Lavish/HarshVardhan | N25: 1 | Q25: Not listed as of 1/8/22- sought listing as well as issue of 12mh till Jul;4h to be rel on 28/9 (14h as on 14/11);8h rel on 3/4[32]; 10h rel on 10/4-to be used in Apr TS[42];10h rel on 8/7[52];16h rel on 29/8[68];16h rel on 14/10[84];12h rel on 25/11[96];16h rel on 30/12[112];7 h rel on 21/2[135];6 h rel on 5/4[141];21h rel on 15/4[162];22h rel on 4/7/25 for Apr & May [184]
A26: B378 | B26: 22 | C26: =2*B26+2*4 | D26: =8*10 | E26: =8*4 | F26: =SUM(C26:E26) | G26: 20 ord Expediting(incl 4ord FD sub exp)+ 2OCS; Inspn: YIL(706)-11/4(1d); (631)-27/4 (1d);Microfinish(611)-30/4 (1d);PO 569 - 23to25/4 (3d);Schneider -PO 725-22-25 (4d);Mtg. with YIL for resolving o/s Hold-ups in FAT & procurement resply;Meeting/rev. of Cryo Test procedure & expediting of o/s issues; Rev. Mtg. @ Kequip Global alongwith Client (28/4-1d);Mtg with ABB at Office for review of orders - 10/4 (8h) | J26: Chandrashekhar/Sumanta Mondal/Ajay Gupta/Rajeev Kr Khandelwal/Prakash Jagarwal/Deepak Dinkar -GAIL Usar | N26: 0 | Q26: 15h relsd on 8/6/22 - auth avl for BT/US;28 h bkd as on 1/8/22- so not asked for anything in Jul;28h rel on 30/8/22;40h rel on 27/9(116h);136 as on 28/10;40mh rel on 6/12(200 as on 6/12);70mh rel on 9/1/23(270 as on 10/1);70 h on 9/2[340];50h in place of 96 sought on 13/3[390];130mh rel on 10/4[520];80 h rel in place of 116 sought[600];bal 36h rel on 18/5 [636];70h rel against 108 sought on 8/6 [706];160h rel against 164 sought on 10/7[866];100h rel on 8/8 against 156 sought[966];60h rel ag.168h sought on 12/9 [1126];185 rel. on 5/10[1311];88h rel in Nov [1399];92h rel on 12/12[1491];130h rel on 5/1[1621]; 356h excess bkd in Dec[1977];114h rel on 2/2[2091]140h rel on 13/3[2231];120h rel on 5/4[2351];92h rel on 13/5;95h rel on 10/7[2598];100h rel on 9/8 [2698];130h rel on 9/9[2828];210 rel on 10/10[3038];140h rel on 13/11[3178]; 140 h rel on 26/12[3318];150h rel on 13/1[3468];100h rel on 21/1[3568];140h rel on 12/2[3708];150 mh rel on 17/3[3858];155 mh rel on 15/4[4009];160mh rel on 20/5[4168]
A27: B359 | D27: 0 | E27: 0 | F27: =SUM(C27:E27) | J27: Chandrashekhar/Sumanta Mondal/Abhishek/Sarvesh Kumar | Q27: 24h relsd on 30/3/22;24h relsd on 2/8/2216mh rel on 5/3/25[232]
A28: B414 | B28: 5 | C28: =2*B28+1*4 | D28: =8*6.5 | E28: 0 | F28: =SUM(C28:E28) | G28: 5 orders ( incl. 3Running orders & 1FD expediting& 1OCS); Insp: Schneider - Sw Bds - B414/55- 22-25/4 (4d);Pace process 5 QAP appls.-12,14/4 (1d), 27,28/4(1.5d); | J28: Himangshu Pal/ Shnaoli Nath | Q28: 96h issued on 6/7/23; B414- 200mh rel on 23/8/23 with time period upto Oct'23(though we had not sought any mh for Jul); [296] ason 13/3 - 133h avl as on 13/3;29h avl as on 8/4;29mh (earl avl) time ext. recd on 13/8/24);212 h rel on 14/10[518]
A29: B436 | B29: 1 | C29: 2 | D29: 0 | E29: 0 | F29: =SUM(C29:E29) | G29: SCADA order on ABB | J29: T Ravi/Sangram Mishra/NS Vasudev | P29: 10h rel on 22/5;26h rel on 12/10[38];12 mh rel on 20/5[50]
A30: B440 | B30: 15 | C30: =2*B30 + 1*4 | D30: =8*0.5 | E30: 0 | F30: =SUM(C30:E30) | G30: Desk expediting, QAP appl if SITP not avl,TPI IRN end.,OCS; 80 +80 Mandays(E+I);1 ord on 2L Eng. Recd on 3/4/23; 8h to be sought in May'23; 2 ord exp-8h for Jul'23; As per HO mail dt 11/9/23, MH are not being relsd & exp. Is being done by Pjts - Accordingly, we may not involve; Spl. reqts for IBA appd tptr & freight upto site. ; For Sep: 4ord exp + Rev & Comments on Technicas Insp. related issues - 27/10/23 ;For Nov: 4 ord exp(incl 1 OCS)+tech. clarification on Tech.Reuni Pkg ord; Dec: 6/12- Appl of WPS/PQR rev of TR pkg; ITP R4 reviewed on 16/1/24; WPS/PQR review/clarifications-12/2; IBR certification clarification-14/2; INSPECTION AND TEST PLAN FOR STRUCUTRUAL STEEL FABRICATION OF RADIANT, HEATER & APH - 03-FF-00-051 on 14/3; IRN rev & endors for Plates & Spares on 18 & 22/3(1d); Revised ICP sub on 19/4; ITP for Pr. Part Fabrication appd on 22/4; ITP for Return Bends-8/5;INSPECTION AND TEST PLAN FOR CASTST RETURN BENDS -app on 17/5, clarifications-29/5;Study & Clarification on IGC reqt-7/6;QAP appl of Exp. Joints & Tube seals(14/6); IL ord 48 0 not yet in EPS; Tech. clar. & doc. rev. of Tecnicas - VFDs TPI doc rev. on 13/8/24; MF EPCG license f/up; Doc rev. & IRN endors. of Centrifugally Cast Support on 13/9; Plantech - Line stop fittings/TOR fittings- Doc rev/IRN endors:Hydrocyclone QAP rev-1/10; TR/ABB-VFD Doc rev/IRN end: 16/10; BHEL/Tmeic VFD insp- 28,29/10;Nov: 16 ord (incl.4 FD expediting)+ Insp: TMeic (BHEL S/o)-Drives-8,18/11;Doc Rev/IRN endors: CGL Drives-19/11;Tecnicas/TLT -ID/FD Fans-20/11; Tecnicas/ABB-VFD-13/11; TR - Rev/IRN endors of Exp.Joints & Tube seals(17/12);12ord exp (incl 1 FD sub);Jan:25: 12ord exp (incl 1 FD sub);Feb25: 12 ord (incl 2 FD sub);Mar25:12 ord (incl 2 FD sub; KSBMIL - Rev. & IRN endorsement of 4 lots Control Valves; Apr25: 15ord( inc 2 ord FD sub+1OCS);PO131-rev/end of TPI recds - 4h | J30: Himangshu Pal/Sanjeev Kumar/Ayush Mathur/Shivaji/VVR Murthy | P30: 24h rel. on 5/10;4h rel on 29/2 [56]8h rel on 5/4[64];12h rel on 17/8[90];20h rel on 17/9[110];:16h rel on 10/10[127];18h rel pn 18/11[145]; 30h rel on 26/12[175];20h rel on 10/2[195] ; 35h rel on 21/4[230];15mh rel on 24/5[245]
A31: B448 | B31: 1 | C31: 0 | D31: =8*4 | E31: =8*0.5 | F31: =SUM(C31:E31) | G31: Insp. & exp. Of Direct ordered items; For LSTK, insp@ payment on manday item rate;resolution of queries on insp from bid till compln. Of pjt;expediting, if reqd. by Owner - Plant Automation tender on ABB - Plant Automation QAP rev. 28/4(0.5d); Inspn: Kalpataru/Schneider - 22-25/4 (4d); | J31: Himangshu Pal/Sanjeev Kumar/UK Mishra/NS Vasudev | Q31: 12 h issued on 11/1;4h rel on 11/3[22];8h rel on 6/4[30];20h rel on 11/5 [50];2h rel on 9/10 (sep ts closed so used in Oct)[56];2h rel on 10/4- to be used in Apr TS[56];18h rel on 22/5[74];4h rel on 1/7[78]; 16h rel on 27/8[110];8h rel on 4/3 [160];32h rel on 21/4[192];60h rel on 8/7[252]
A32: B519 | B32: 3 | C32: =2*B32+1*4 | D32: 0 | E32: 0 | F32: =SUM(C32:E32) | G32: As per Pjt Prof, desk expediting by HO team, unless specifically sought from RPO(critical items). -Insp.(within4 days of call) & FD cert. by us - OCS not applicable. Insp @MIL -PO6823- 22/11; Insp@MIL on 9/12; Mtg. with YIL to expedite Analyser order (being followed up by Client); Mar25: 4 ord expediting - Check OCS status of B519/6821-YIL - shown o/s in Consolidated EPS rept; Apr'25: 2 runn ord (FD exp)+1OCS | J32: Chandrashekhar/HarshVardan/Prakash Jagarwal/DSNMurty
A33: B560 | B33: 14 | C33: =2*B33 | E33: 8 | F33: =SUM(C33:E33) | G33: Req.from ED(I) for expediting on 15/6 - 14 orders (incl.3 FD exp & OCS for 7 earlier orders) & OCS also to be made as per latest reqt.; Rev. Mtg @ MF alongwith Client - 30/4(1d) | J33: Chandrashekhar/Vinod Kumar/RK Medhavi | P33: 100h rel on 23/4
A34: B548 | B34: 0 | C34: 0 | D34: 0 | E34: 0 | F34: =SUM(C34:E34) | G34: Alleima- Exchanger - Exp+QAP comments - ITP R1- rev-6/2; Control Panel ITP rev- 7/2; FAT of TCP rev-12/2; Mtg/communications for resolution of issue w.r.t Heating Element MOC - 6,9/2; Nov: 1 OCS + Insp. - Emerson S/o on Microfinish - 27/11 & 20/12 | J34: HP/Sanjeev Kr/T Ravi/NS Vasudev/Sanjeev Kr Gupta | P34: 8h all on 30/5;4h on 7/8[20];Dec/Jan/Feb-4h each[32];4h rel on 10/4- Mar TS closed- to be used in Apr[36];4h rel on 24/6[40];4h rel on 9/7[44];4h rel on 12/9[48];4h rel on 30/12[52];12h rel on 30/12[64]
A35: B589 | B35: 0 | C35: 0 | D35: 0 | E35: 0 | F35: 0 | G35: 1 Ord on FS - expediting FD | J35: Himangshu Pal/Sanjeev Kr/T Ravi/NS Vasudev/Sanjeev Kr Gupta | P35: 8h rel on 6/6;8h on 7/8[18];8in oct,8 in dec,4 in Jan[38];12 on 5/4[50];8h rel on 10/4-Mar TS closed - to be used in Apr.[58];8h rel on 24/6[64];8h rel on 17/8[78];8h rel on 5/9[86];8h rel on 11/9[94]
A36: B559 | B36: 4 | C36: =2*B36 | D36: 0 | E36: 0 | F36: =SUM(C36:E36) | G36: 4 orders expediting | J36: Sanjay Choudhary/SK Gayen/RK Gupta | P36: 86h rel on 13/3 [86];104h rel on 1/4[190]; 72 sought for Apr- 160 issued considering upcoming Chiller insp (88h extra avl. For May'24[350]-20h rel on 29/5[370];60mh rel on 1/7[386];20mh rel on 1/8[406];16h rel on 25/10[422]
A37: B650 | B37: 1 | C37: 2 | G37: No scope for RPO - however, OCS to be done | J37: Chandrashekhar
A38: B653 | B38: 14 | C38: =2*B38+1*4 | E38: 8 | F38: =SUM(C38:E38) | G38: Expediting by RPOs as per email dtd 22/10/24, OCS by RPO as per CS mail dt 17/1; (13 running ord+1OCS);Univ Insts -Rev. mtg & Show Cause Notice issue reco. -8h | J38: Sanjeev Kumar/Aasheesh Handa/Amandeep Kaur | P38: 40h rel on 9/4/24 [40]
A39: B725 | B39: 3 | D39: =8*0.5 | E39: 0 | F39: =SUM(C39:E39) | G39: No expediting; Flowserve-rev. of Test Repts -11/4(0.5d) | J39: Himangshu/Sanjeev Kumar- Scope: Rev. of ITP,Insp Docs & FD | P39: 4h sought by BT on 27/5 to Sanjeev Kr
A40: B795 | D40: 0 | F40: =SUM(C40:E40) | J40: G Suresh/Patra/Uday Pratap/Rajeev Chak/NS Vasudev | P40: 32h rels. On 12/9;64h on 16/1; addl 100h rel on 20/1 [276]
...

Sheet Apr25
A1: RPO : Bengaluru | D1: LOCATION CODE : 18-42-506 | H1: MONTH : Apr'25 | M1: Total MH reqd: | O1: =20*8*6
A2: Job No | B2: Number of Purchase Orders | C2: No of Engineers deployed | D2: No of Inspn / Expediting Visits | E2: No of Expediting Reports / Desk expediting | F2: No of OCRs | G2: Manhours for Inspection | H2: Manhours for expediting | I2: Others | J2: Total Manhours required | K2: Recd as on 03/06/25 | L2: Shortfall
A3: Holiday
A4: Leave | J4: =8*9.5 | K4: 76 | M4: VR:; AG:11(0.5),12(1d),22(1d);SV-3;US: ;BT-21-25 (5d);NV:1(1d)
A5: 8518 | J5: 200 | K5: 98 | L5: =J5-K5 | M5: Admin works,Insp Guidelines/Typ Test review/ITP revision(E&I ITPS)/Std. Spec review-mtgs with Inst. Engg. on Cryo Test Procedure & Flow Meter MR improvements,other miscellaneous works incl. Dept Mtg, Office enhancement efforts,Short Term Contracts, New Facility Mgmt Tender requirements freeze etc.,Mktg leads, Hosp Nomination;98h avl on 27/5 | V5: pending mh to be filled: | X5: MH avl
A6: 4994 | J6: 72 | K6: 72 | L6: =J6-K6 | M6: Enlistment:SBEE-16/4(16h); Fluidyne - 25/4(16h);Enh: 2L Engrs (29/4-16h);,Reval:ABB(29/4); Shifting of works +Revalidation: Godrej Bus Duct(30/4); Visit to Weir Min. on 16/4(1d) for potential enlistment;72h rel on 27/5[4310]
A7: 7716 | I7: 12 | J7: =SUM(G7:I7) | K7: 16 | L7: =J7-K7 | M7: Godrej/Climaveneta -VC on 7/4 (0.5d); Compliance review on 15 & 17/4 - (1d);16h rel on 9/4[28] - utilised in Mar'25
A8: 8590 (Training) | L8: =J8-K8
A9: B035 | H9: 8 | J9: =SUM(G9:I9) | L9: =J9-K9 | M9: Expediting - Greensol;
A10: B038 | F10: 1 | H10: 4 | J10: =SUM(G10:I10) | L10: =J10-K10 | M10: Apr- 2ord (incl 1OCS) -4h
A11: B058 | L11: =J11-K11 | M11: Insp of Drives @ Yaskawa a/c FL Smidth -5,6/2/25 + doc rev. 28/2 | V11: Viji | W11: 168
A12: B224 | G12: 40 | J12: =SUM(G12:I12) | L12: =J12-K12 | M12: 3 Insp Visits: Insp: L&T /YIL -Doc rev+IRN end-5/4(0.5d);Afcons/Emerson-UFM- Doc/Compliance rev - 2/4 (0.5d);YIL - Shelters - Inlet Pump Skids Insp - 7/4 - (1d) ; Amounting to -16h 5nos Doc Rev & Expediting:Koso Valve QAP appl (17/4 - 0.5d);Vertiv ACDB QAP-28/4 (0.5d);Motor- ABB Finland, Vertiv -ACDBs with Static switch - QAP appl - 4h; VSD- Hitachi,Korea; TPI doc. Rev. - 4hrs on 21 & 4h on 28/4 (1d);Schneider 6.6kV QAP appl -2/4-(0.5d); Amounting to 24h;
A13: B215 | L13: =J13-K13
A14: B229 | B14: 3 | F14: 2 | H14: 14 | J14: =SUM(G14:I14) | L14: =J14-K14 | M14: 1order FD f/up +2 OCS
A15: B269 | B15: 16 | F15: 2 | G15: 64 | H15: 40 | I15: 0 | J15: =SUM(G15:I15) | K15: 0 | L15: =J15-K15 | M15: 11 running orders+ 3Orders FD sub expediting+2OCS; Critical Item Insp - YIL- RHCU FAT- 5d (28/4-2/5-(5d); FF Doc Rev/IRN endor - 26/4(1d);YIL -B269/1408 -Shelter-11/4(1d); Mtg with ABB at Office for review of orders - 10/4 (8h) | V15: SV | W15: =21*8-4*8 | X15: =90+24+22 | Y15: b035+b436+B767
A16: B297 | B16: 6 | F16: 1 | G16: 8 | H16: 18 | J16: =SUM(G16:I16) | L16: =J16-K16 | M16: Exp-6 ord-4 runn ord, 2-FD sub; 1OCS; Insp: B297/301 (4/4 - 1d)
A17: B302 | B17: 4 | H17: 16 | I17: 16 | J17: =SUM(G17:I17) | L17: =J17-K17 | M17: 4 Running orders ; Shirdi Sai -Online mtg/QAP appls, KOM for Turnkey Inst. Job - YIL
A18: B348 | B18: 14 | H18: 32 | J18: =SUM(G18:I18) | K18: 22 | L18: =J18-K18 | M18: 12 Running orders +2 ord FD exp-22h rel on 4/7/25 for Apr & May [184]
A19: B378 | B19: 22 | F19: 2 | G19: 80 | H19: 52 | I19: 32 | J19: =SUM(G19:I19) | K19: 160 | L19: =J19-K19 | M19: 20 ord Expediting(incl 4ord FD sub exp)+ 2OCS; Inspn: YIL(706)-11/4(1d); (631)-27/4 (1d);Microfinish(611)-30/4 (1d);PO 569 - 23to25/4 (3d);Schneider -PO 725-22-25 (4d);Mtg. with YIL for resolving o/s Hold-ups in FAT & procurement resply;Meeting/rev. of Cryo Test procedure & expediting of o/s issues; Rev. Mtg. @ Kequip Global alongwith Client (28/4-1d);Mtg with ABB at Office for review of orders - 10/4 (8h); 160 mh rel on 20/5 | V19: NV | W19: =168-16 | X19: =30+2 | Y19: b414
A20: B414 | B20: 5 | F20: 1 | G20: 52 | H20: 14 | J20: =SUM(G20:I20) | L20: =J20-K20 | M20: 5 orders ( incl. 3Running orders & 1FD expediting& 1OCS); Insp: Schneider - Sw Bds - B414/55- 22-25/4 (4d);Pace process 5 QAP appls.-12,14/4 (1d), 27,28/4(1.5d); | V20: Shortage | W20: =168+152-32
A21: B436 | B21: 1 | H21: 2 | J21: =SUM(G21:I21) | K21: 12 | L21: =J21-K21 | M21: SCADA order on ABB-12mh rel on 20/5
A22: B440 | B22: 15 | F22: 1 | G22: 4 | H22: 34 | J22: =SUM(G22:I22) | K22: 15 | L22: =J22-K22 | M22: Apr25: 15ord( inc 2 ord FD sub+1OCS);PO131-rev/end of TPI recds - 4h;15h rel on 24/5
A23: B448 | B23: 1 | G23: 32 | I23: 4 | J23: =SUM(G23:I23) | K23: 60 | L23: =J23-K23 | M23: Plant Automation tender on ABB - Plant Automation QAP rev. 28/4(0.5d); Inspn: Kalpataru/Schneider - 22-25/4 (4d); 60h rel on 8/7[252]
A24: B519 | B24: 3 | F24: 1 | H24: 10 | J24: =SUM(G24:I24) | L24: =J24-K24 | M24: Apr'25: 2 runn ord (FD exp)+1OCS
A25: B548 | L25: =J25-K25 | X25: =122+168
A26: B560 | B26: 14 | H26: 28 | I26: 8 | J26: =SUM(G26:I26) | L26: =J26-K26 | M26: 14 orders (incl.3 FD exp & OCS for 7 earlier orders) & OCS also to be made as per latest reqt.; Rev. Mtg @ MF alongwith Client - 30/4(1d)
A27: B589 | L27: =J27-K27
A28: B559 | B28: 4 | H28: 8 | J28: =SUM(G28:I28) | K28: 1 | L28: =J28-K28 | M28: 4 orders expediting - 1h rel on 24/6
A29: B650 | L29: =J29-K29
A30: B653 | B30: 14 | H30: 32 | I30: 8 | J30: =SUM(G30:I30) | L30: =J30-K30 | M30: (13 running ord+1OCS);Univ Insts -Rev. mtg & Show Cause Notice issue reco. -8h
A31: 6979 | L31: =J31-K31 | M31: Being given in lieu of B302-40h given
A32: B725 | B32: 1 | H32: 4 | J32: =SUM(G32:I32) | L32: =J32-K32 | M32: Flowserve-rev. of Test Repts -11/4(0.5d)
A33: B767 | B33: 1 | I33: 8 | J33: =SUM(G33:I33) | L33: =J33-K33 | M33: Rev. of Methodology - 8h
A34: B795 | L34: =J34-K34 | M34: Essenar t/f QAP appl (9/3)
A35: B903 | B35: 2 | H35: 4 | J35: =SUM(G35:I35) | K35: 10 | L35: =J35-K35 | M35: 2 Orders -10h rel on 2/7[10]
A36: B904 | B36: 1 | H36: 2 | J36: =SUM(G36:I36) | K36: 4 | L36: =J36-K36 | M36: 1 Order -4h rel on 2/7[4]
A37: TOTAL | G37: =SUM(G4:G36) | H37: =SUM(H4:H36) | I37: =SUM(I4:I36) | J37: =SUM(J4:J36) | K37: =SUM(K4:K34) | L37: =J37-K37
A42: Guidelines :
A43: 1. Inspection Visit including review and endorsement of final documents: At actual
A44: 2. Expediting and preparation of expediting report: Average 2 hours /month /order ( No separate man hours for coordination )
...

Sheet ConsolidatedMHrequirementMay25
A1: Consolidated man hour requirement for May'25
A2: =(21*8*6)
A3: Job No | B3: No. of orders | C3: Exp. | D3: Inspn | E3: Others | F3: Total | G3: *Others/ Remarks | J3: Insp/ Project Coordinators | N3: MH available as on | O3: MH to be released for May'25 | P3: Allotted | Q3: 8518 reqd
A4: 4994 | B4: 3 | E4: =8*4 | F4: =SUM(C4:E4) | G4: Reval:Lighting Tech(2/5);Enl.:SBEE(7/5);Visit to CPRI for C&S type test & Interaction with Balaji Electro Controls for potential supplier (1d) | J4: Rajesh Sinha | N4: 0 | O4: 32 | P4: 0 | Q4: 32h relsd on 14/1;40h relsd on 18/2;96 hr relsd on 16/3/20;24h relsd on 23/6;16hr allotted on 23/9; 32h issued on 28/6;40mh rels on 25/11;48h relsd on 1/2/22;56h issued on 21/3/22;16h relsd on 2/5/22;32 h rel on 27/6;32h rel on 30/11;24h rel on 9/2;32h rel on 28/3;36h ;32h rel on 22/5[3998]on 1/5;48h rel on 31/5;64h rel on 27/6;64h rel on 27/7;28h rel on 11/9 against 32 sought;8mh of Sep rel on 16/10;[3844 upto 8/1]40h rel on 8/1;48h rel on 1/4[3976];32h rel on 22/5[4006];36h on 4/6[4042];48h rel on 29/10[4154];44h for Nov & Dec, rel. on 3/1/25[4198};24h rel on 10/2 [4222];- 16h rel on 22/4[4238];72h rel on 27/5[4310];32h rel on 25/6[4342]
A5: 6979 | F5: 0 | Q5: 60h rel on 14/10 against MH for Vert. B; 36h rel on 8/1 in lieu of B302 [96];in lieu of B302106 mh rel against 6979 on 21/4 (for Jan/Feb/Mar) 6979-[202]
A6: 7716 | D6: 0 | E6: =8*0 | F6: =SUM(C6:E6) | J6: Sanjeev Kumar/ Yatendra Agrawal - EIB Renovation | P6: 16h rel on 9/4 against Climaveneta order referred in 8590 above [28]
A7: 8518 | B7: 0 | C7: 0 | D7: 0 | F7: 200 | G7: Admin works,Insp Guidelines/Typ Test review/ITP revision(E&I ITPS)/Std. Spec review-mtgs with Inst. Engg. on Cryo Test Procedure & Flow Meter MR improvements,other miscellaneous works incl. Dept Mtg, Office enhancement efforts,Short Term Contracts, New Facility Mgmt Tender requirements freeze etc.,Mktg leads, Hosp Nomination;ITP for Aircooled Exchangers & Wiremesh Demister-12/5,Heat Exch &Columns-13/5+3 ITPs for Vessels/Columns/Reactors (30/5) | J7: Tech Develop & OH | N7: 300 | Q7: 123h avl as on 27/6/22(2200 in 8518-02);300mh issued on 8/8/22 (tot. 2800mh/2521 consumed as of 8/8) - 2679 consumed as on 16/8- 121 hrs avl.[254h consumed in Jul'22]; 200h relsd on 6/9 in place of 300 sought (3000 as on 6/9/22);300 mh rel on 13/10 - 3300 as on 13/10;200h rel on 14/12[3500 as on 15/12];200h rel on 13/1/23[3800 as on 19/1/23] (176h avl. as on 19/1, after closure of Dec TS); 300mh rel on 20/2/23 against 8518-00 [15100-12657=2443mh];1836h rel on 18/3 -15998;for Apr MH, 418 mh rel on 4/6/24[15348];410 mh rel on 16/7[16408];60mh utilised in Sep [17331];417 mh rel. on 11/12 for Oct[17748];500mh rel on 17/1[18248];125 mh rel on 23/1[18373];316h rel on 4/3[18673];200h rel on 24/4[19398]
A8: 8590 | D8: 0 | F8: =SUM(C8:E8)
A9: B016 | B9: 0 | C9: 0 | E9: 0 | F9: 0 | J9: Uday Pratap Singh/Pankaj Saxena/Alok Singh | Q9: 10h issued on 2/5[1714];16h rel on 2/7[1722];8h rel on 12/9[1730] for VFD
A10: B035 | B10: 1 | C10: =1*8 | D10: 0 | E10: 0 | F10: =C10+D10+E10 | G10: Expediting - Greensol; | J10: Saeed Akhtar/ D Jana | N10: 0 | O10: =F10-N10 | Q10: 47 hr avl on 19/7;64 h already bkd in jul; 28 hrs relsd on 16/11;24h relsd on 18/12;24h relsd on 14/1;32h issued-RAM val extn for YVT reqd;16 h on 16/3/20;16h relsd on 23/6/20; J/F/M request:80/40/40; 96 hrs given on 4/2/21'40h on 30/3/21;16h allotted on 28/6;40h relsd on 25/8;24h relsd on 26/10;32h relsd on25/11;24 h rel. in Dec;24h rel on 3/2/22;8h relsd on 1/8/22;8h relsd on 29/8;32h rel on 27/9;8h rel on 10/1[1249];8h on 9/2[1257];8h on 1/5[1275];8h on 31/5[1283];8h on 28/7[1291];8 h on 15/9[1307];8 h on 26/9[1315];32h rel on 1/12[1407;32h rel on 8/1[1471]; 8h+ 4h(B302) rel on 12/2[1483];8h +6h(B302) rel on 11/3[1497];8h rel on 1/4[1505];8h rel on 13/5[1513];16h for May & Jun rel on 1/7[1539];8h rel on 9/8[1555] 90h rel on 12/10 [1645]-10h bal c/f to Oct;8h rel on 28/2[1653]
A11: B038 | B11: 1 | C11: =2*B11 | D11: 0 | E11: 0 | F11: =C11+D11+E11 | G11: Expediting/fin.doc subm followup & OCS prep(16 nos) - 24h sought for Time ex.of YIL & other activities of past for CPCL on 22/12/21 - 16h relsd on 31/12/21; 1 Ord on FS recd in Oct-4h rel on 28/10; 8h sought on 5/12; Dec: 2 OCS +5 run. Ord. expediting - 28h sought (8h rel); Jan: 5 run ord +2 FD exp,Sandvik Mtgs - 36h sought - 12h rel [32];FEb- 20h sought-none relsd; Mar:32h sought- 16h issued; Meeting at Sandvik on 11/4/23 with MRPL; Apr:5 running orders+3FD expediting(32h)- total:40h sought - May: Alliema VC on 16/5/23;5 running orders+3FD expediting(32h)- 40h sought; 6r orders+2 OCS+Alliema expediting - 40h sought in Jun-16 relsd.[120];40 sought in Jul(8 ord+Alleima- exp incl. mtg on 26/7)); 36h sought in Aug- incl.7 orders(4 running) & Alleima Expediting [64 h sought on 28/8 incl. 28h short of Jul]; [20 h relsd [168] ;6 orders expediting- 24h;6 orders expediting;1 OCS on 12/9;Alleima expediting including visits to Hosur works on 1 & 7/9;Oct: 1 OCS done(704), 5 orders expediting- sought 24h;Nov: 7ord exp- 14hrs sought; Dec: 7 order expediting - 14h +4h- mtg with Head of Swims& IL for urgent intervention; Jan:7 ord exp - 14h(not rel); Feb:2Runn ord exp +1OCS+4FD exp; Mar: 2 Runn ord+3FDsub exp+1 OCS; Mtg with YIL on 7/3/24 for Turnkey Instn Job;Apr: 1 Rord;3 FD exp+1OCS;mtg with YIL -29/4; May: 2 FD exp+1OCS+ 1Rord Exp -8h;Jun: 1FD exp+1OCS+1Rord Exp-6h; Jul: 1ord fd exp; 1ord- YIL - excl.exp. with mtgs & daily f/ups; Aug- 2 ord - 4h; Sep-2 ord FD - 4h; Oct-2ord FD-4h ;Nov-2ord FD-4h;Dec-2ord FD-4h;Jan,Feb,Mar-2ord FD-4h; Apr- 2ord (incl 1OCS) -4h;May-1ord FD exp. | J11: Himanghsu Pal/Sanjeev Kumar/Aasheesh Handa | N11: 0 | O11: =F11-N11 | Q11: 60 hr allocated on 22/2/19 (first time); 140 hrs allotted on 26/4/19; 200h relsd on 7/8/19; 40 hrs relsd on 5/11/19;50 hrs relsd on 13/1/20;40 hr relsd on 20/2;;Bal. MH reqd from May'20 till completion of activities: 8 orders - 3 orders can get completed by Jul'20; bal 5 orders will go upto Sept- so Exp:3*3*4+5*5*4=136hrs;FD/OCS-29 orders -29*4*3=348 - So total - 484 mh; 16 hrs avl as on 27/5/20; 20 hrs avl. as on 20/8- RAM auth to be chkd;130h allotted on 29/9 - till end of pjt -brk up 40(sep),40(oct),50(Nov);16h relsd on 31/12/21;8h rel on 12/12; 8h rel on 6/1/23;12mh rel on 17/2 against 36 sought[32] b038-02;16h ag.20hsought on 27/2[48]; 16h rel on 6/4 against 20 sought[64];22h given against 40 sought on 15/5/23 [88];16h given in place of 40 on 19/6[104];12h (in place of 40h) rel on 8/8[132];28h rel on 7/9[160];16h rel on 9/10-sep ts closed - so used for Oct[184];26h rel on 18/12[210];10h on 11/1[220];7h rel on 4/3/24[234];16h rel for Mar [250];;8h on 4/6[270]8h rel on 4/8[278]
A12: B058 | B12: 1 | C12: 0 | F12: 0 | J12: Patra/Sanjay Dhuria | Q12: 8h rel on 1/8
A13: B224 | B13: 1 | F13: =8*9.5 | G13: Tecnip/Micon -insp- 22/5(1d);L&T/YIL-Wireless Insts- 30/5(1d);L&T/YIL Moist Anal Rev/IRN end.- 1/5 (0.5d);JSW-Rev/IRN end of Elec Pkg-6/5 (1d);MEIL-SRU/Cords&KEC QAP rev -8/5(0.5d);Megha/PPU-All elec. Items TPI IRN rev-6/5(1d);Meil-SRU- Mass FM,Mag FM -QAP rev-21/5(1d);Meil/SRU/Nexon Cable QAP rev-27/5(0.5d);MEIL/SRU-PRV QAP-19/5(0.5d);Meil/SRU/Chabi-QAP-27/5(0.5d); | J13: Mr Dipak Panchal / Mr Sunil Saurabh/ Mr R.K.Mohabe/Neena Mukherjee | N13: 0 | O13: 56 | Q13: 20 hrs issued on 9/20- addl 48 hrs provided on 18/11/20;48h recd on 8/1/21;64 mh against B224-05 recd on 14/5/21;56 h on 1/6/21;140h relsd on 6/12/21;190h relsd on 28/12/21;112h relsd on 2/2/22;64h relsd on 28/2/22;216h relsd on 28/3/22;88h relsd on 4/5/22;80h relsd on 29/6/22;80h relsd on 1/8/22;316h against all units relsd on 28/9 in unit 00; 114h relsd on 3/11/22; 120 h relsd on 4/12 against req. of 212h(804 in Unit 00 as on 6/12); 300 rel. on 6/1 in place of 388 sought [1104];172h rel on 172 on 16/2[1276];256h rel on 7/3[1532];300h (against 360 sought) rel on 5/4[1832];304h rel on 12/5[2136];300mh rel on 31/5 against 408 sought [2436]; 200h rel on 9/8 (264 sought)[3039]; 440h sought on 28/8 & resld on 11/9; 372h sought on 26/9- relsd on 4/10; 301 hr rel. for Nov & Dec against 480 sought on 8/1/24[4482];240mh issued on22/2 (against 252 sought) [4735];150h rel on 1/4 for feb & 150h rel on 6/4 for mar[5035];96h rel on 21/5[5131];96h rel on 2/7/24 (for May'24)[5227];272h rel on 16/7[5499]; 40h rel on 12/10[5635];90h rel on 10/1[5720];100h rel on 20/1[5820];21h rel on 10/2[5841];307h rel for Jan-Mar on 24/4
A14: B229 | B14: 0 | C14: =2*B14 | E14: 0 | F14: =SUM(C14:E14) | J14: Patra/JPS Kalra/DK Kesri | Q14: 40 hrs relsd on 13/8/21; 16 hr to be relsd on 29/9;24 hrs relsd on 31/12;24h relsd on 8/2/22;24h relsd on 9/5/22'20h resld on 9/6/22;24h relsd on 15/7;228 consumed as on 1/8/22;20 h relsd on 2/8/22; 20h resld on 12/9/22;24h relsd on 3/10;10h rel on 9/12;28h rel on 9/1[345];48h rel on 14/3 for Jan/Feb [393];20h rel on 17/4[413];20h rel on 15/5[433];36h rel on 22/6[469];32h rel on 11/7[501];56 h sought for Jul(32)+Aug(24) on 28/8 - 32h of Jul rel. on 11/9[533];16h rel on 5/10[549];20h rel on 29/11[569];40h rel on 27/12[609];30h on 10/1[639];40h on 21/2[679];16h on 29/3[695];30h on 5/4[725];;16h rel on 16/5[741];-16h rel on 16/7[757]; 24 h rel on 12/10 but not utilised since Name appl. Not yet recd - to be c/f to Oct[765];10h rel on 10/12[775]; 100h rel on 23/1[883;8h rel on 6/3 [901]
A15: B269 | B15: 17 | C15: =2*B15+4*2 | D15: =8*6.5 | E15: =8*3 | F15: =SUM(C15:E15) | G15: 12 running orders+ 4Orders FD sub expediting+1OCS; Critical Item Insp - YIL- RHCU FAT- 5d (28/4-2/5-(5d); BDK visit- 21-23/5(3d)-posting for expediting rectification/replacement of valves recd.frm site;YIL-1415- RHCU FAT compl- 29/5(1d);Cables Rev/IRN endor - 28/5(0.5d);For Apr+May-38mh rel on 19/6 (against 104+118=222h sought)[1476];Another 100mh rel on 20/6[1576] | J15: Chandrashekhar/Rajesh Bhatla/Arun Singh Arya/Sanjay Chaudhary | N15: 0 | Q15: ;32h rel in place of 60h sought on 15/6[532];48h rel on 10/7 in pl. of 76 sought[580];36h (80 sought)rel on 8/8[640]; 49 h rel on ag. 88 sought on18/9 [689];96h rel on 4/10[785] ;42h rel on 29/11(for month of Oct)[827];30h rel on11/1 [857];80h rel on 18/1[937];40h rel on 19/2[977];24h rel against 50h sought on 13/3[1001];36h rel on 10/4[1037]-to be used in Apr since Mar TS already closed.;20mh rel on 2/7(for may)[1057];27h rel on 10/7[1084];40h rel on 9/8[1124]; 20h rel on 12/10[1174];48h rel on 30/12[1222];20mh rel on 8/1[1242];100h addl given on 20/1[1342];50h rel on 19/2[1392];30h rel on 19/3[1422];16mh rel on 17/4 [1438];For Apr+May-38mh rel on 19/6 (against 104+118=222h sought)[1476]
A16: B285 | F16: 0 | J16: Sanjeev Kumar/Vikalp Paliwal
A17: B297 | B17: 6 | C17: =7*2+4 | D17: 8 | E17: 0 | F17: =SUM(C17:E17) | G17: Exp-6 ord-4 runn ord, 2-FD sub exp; Insp: B297/308 (23/5 - 1d) | J17: Chandrashekar/NS Vasudev/Manish Tiwari - GAIL Pata | N17: 10 | Q17: 24h allotted on 25/2/22;44 h allotted on 2/6/22(against 64 sought) - 60h bkd in Jun correspond to previous month; jun rel. not happened sought 88h for Jun/Jul [128 h as of 11/8/22]-80h issued on 22/8/22; 28h resld on 25/8; 232h as on 6/9/22;268 as on 28/10(32 h rel for Sep being util. in Oct);30mh rel on 11/11;40 h rel on 7/12(338 as on 7/12);40h issued on 11/1 [378];30mh issued in Feb 10h avl on 9/2[408];46h given on 9/3 in pl of 68 sought [454]; 100h rel on 6/6 for May'23[554];40 on 8/7 in pl. of 184 h sought[594];20h rel on 9/10- sep ts closed so used in Oct [614] 30h rel for Oct[644]; 32 h rel on 15/12 against 58 sought[676];24h rel on 12/3 ag. 58 sought[755];18h rel on 5/4[773];16h rel on 15/5[789];16h rel on 24/6 [805];32;8h rel on 11/3 [965]h rel on 12/7[837];24h rel on 12/8[861];20h rel on 10/9[881];16h rel on 14/10[897]; 24h rel on 19/11[921];16h rel on 10/12[937];20h rel on 13/1[957];8h rel on 17/3[965]
A18: B302 | B18: 4 | C18: =2*4+4*2 | D18: =8*6 | E18: 16 | F18: =SUM(C18:E18) | G18: 4 Running orders ; 8731-KEPL/TMEIC-Drives insp- 22-27/5 (5d);2162-KSBMIL-26/5(1d);Shirdi Sai -Online mtg/clarifications | J18: Suresh/D Jana(302-1)/Sivakumar(302-2)/Abhishek Rai/Balbir Singh (01-P/L & 02- COT) - pump order - 02; FOA also to incl. Unit no for correlation | Q18: 8hr allotted on 31/10/21;4h all. On 30/11;16h relsd on 6/2/22;56h relsd against B302-01 on 1/4/22;56h of Mar'22 of 02 unit relsd on 4/5/22;36h for Jul/Aug/Sep'23 relsd against B035 on 3/10;4h rel against B035 on 12/2;10h rel against B035 on 29/5[1523];106 mh rel against 6979 on 21/4 (for Jan/Feb/Mar) 6979-[202]
A19: B348 | B19: 15 | C19: =2*B19+2*2 | D19: 0 | E19: 0 | F19: =SUM(C19:E19) | G19: 13 Running orders +2OCS | J19: Himangshu/Sanjeev Kumar/Lavish/HarshVardhan | N19: 1 | Q19: Not listed as of 1/8/22- sought listing as well as issue of 12mh till Jul;4h to be rel on 28/9 (14h as on 14/11);8h rel on 3/4[32]; 10h rel on 10/4-to be used in Apr TS[42];10h rel on 8/7[52];16h rel on 29/8[68];16h rel on 14/10[84];12h rel on 25/11[96];16h rel on 30/12[112];7 h rel on 21/2[135];6 h rel on 5/4[141];21h rel on 15/4[162];22h rel on 4/7/25 for Apr & May [184]
A20: B359 | D20: 0 | E20: 0 | F20: =SUM(C20:E20) | J20: Chandrashekhar/Sumanta Mondal/Abhishek/Sarvesh Kumar | Q20: 24h relsd on 30/3/22;24h relsd on 2/8/2216mh rel on 5/3/25[232]
A21: B378 | B21: 20 | C21: =2*B21+2*4 | D21: =8*13.5 | E21: =8*3 | F21: =SUM(C21:E21) | G21: 20 ord Expediting(incl 7ord FD sub exp); Inspn: YIL(639-U&O/PP FAT))-2,30/5(2d); (706-Rev/IRN end)-3/5(.5d);ABB(569)-29/5(1d);Schneider -PO 725-7-9,28-30,Rev:26/5 (6.5d);Paramount/C&S-8,9,15,16/5(4d);Mtg. with YIL for resolving o/s Hold-ups in FAT & procurement resply;Meeting/rev. of Cryo Test procedure & expediting of o/s issues; Rev. Mtg. @ YIL alongwith Client -9,15,30/5-(2d); | J21: Chandrashekhar/Sumanta Mondal/Ajay Gupta/Rajeev Kr Khandelwal/Prakash Jagarwal/Deepak Dinkar -GAIL Usar | N21: 0 | Q21: 15h relsd on 8/6/22 - auth avl for BT/US;28 h bkd as on 1/8/22- so not asked for anything in Jul;28h rel on 30/8/22;40h rel on 27/9(116h);136 as on 28/10;40mh rel on 6/12(200 as on 6/12);70mh rel on 9/1/23(270 as on 10/1);70 h on 9/2[340];50h in place of 96 sought on 13/3[390];130mh rel on 10/4[520];80 h rel in place of 116 sought[600];bal 36h rel on 18/5 [636];70h rel against 108 sought on 8/6 [706];160h rel against 164 sought on 10/7[866];100h rel on 8/8 against 156 sought[966];60h rel ag.168h sought on 12/9 [1126];185 rel. on 5/10[1311];88h rel in Nov [1399];92h rel on 12/12[1491];130h rel on 5/1[1621]; 356h excess bkd in Dec[1977];114h rel on 2/2[2091]140h rel on 13/3[2231];120h rel on 5/4[2351];92h rel on 13/5;95h rel on 10/7[2598];100h rel on 9/8 [2698];130h rel on 9/9[2828];210 rel on 10/10[3038];140h rel on 13/11[3178]; 140 h rel on 26/12[3318];150h rel on 13/1[3468];100h rel on 21/1[3568];140h rel on 12/2[3708];150 mh rel on 17/3[3858];155 mh rel on 15/4[4009];160h rel on 20/5; 160h rel on 16/6[4328]
A22: B414 | B22: 4 | C22: =2*B22+1*4 | D22: =8*5 | E22: 0 | F22: =SUM(C22:E22) | G22: 4 orders ( incl. 3Running orders & 1FD expediting); Insp: Schneider - Sw Bds - B414/55- 7-9,29,Rev:26/5 (4.5d);Pace process/Schneider QAP appls.-27/5(0.5d); | J22: Himangshu Pal/ Shnaoli Nath | Q22: 96h issued on 6/7/23; B414- 200mh rel on 23/8/23 with time period upto Oct'23(though we had not sought any mh for Jul); [296] ason 13/3 - 133h avl as on 13/3;29h avl as on 8/4;29mh (earl avl) time ext. recd on 13/8/24);212 h rel on 14/10[518]
A23: B436 | B23: 1 | C23: 2 | D23: 0 | E23: 0 | F23: =SUM(C23:E23) | G23: SCADA order on ABB | J23: T Ravi/Sangram Mishra/NS Vasudev | P23: 10h rel on 22/5;26h rel on 12/10[38]
A24: B440 | B24: 16 | C24: =2*B24 + 1*4 | D24: 0 | E24: 0 | F24: =SUM(C24:E24) | G24: Desk expediting, QAP appl if SITP not avl,TPI IRN end.,OCS; 80 +80 Mandays(E+I);1 ord on 2L Eng. Recd on 3/4/23; 8h to be sought in May'23; 2 ord exp-8h for Jul'23; As per HO mail dt 11/9/23, MH are not being relsd & exp. Is being done by Pjts - Accordingly, we may not involve; Spl. reqts for IBA appd tptr & freight upto site. ; For Sep: 4ord exp + Rev & Comments on Technicas Insp. related issues - 27/10/23 ;For Nov: 4 ord exp(incl 1 OCS)+tech. clarification on Tech.Reuni Pkg ord; Dec: 6/12- Appl of WPS/PQR rev of TR pkg; ITP R4 reviewed on 16/1/24; WPS/PQR review/clarifications-12/2; IBR certification clarification-14/2; INSPECTION AND TEST PLAN FOR STRUCUTRUAL STEEL FABRICATION OF RADIANT, HEATER & APH - 03-FF-00-051 on 14/3; IRN rev & endors for Plates & Spares on 18 & 22/3(1d); Revised ICP sub on 19/4; ITP for Pr. Part Fabrication appd on 22/4; ITP for Return Bends-8/5;INSPECTION AND TEST PLAN FOR CASTST RETURN BENDS -app on 17/5, clarifications-29/5;Study & Clarification on IGC reqt-7/6;QAP appl of Exp. Joints & Tube seals(14/6); IL ord 48 0 not yet in EPS; Tech. clar. & doc. rev. of Tecnicas - VFDs TPI doc rev. on 13/8/24; MF EPCG license f/up; Doc rev. & IRN endors. of Centrifugally Cast Support on 13/9; Plantech - Line stop fittings/TOR fittings- Doc rev/IRN endors:Hydrocyclone QAP rev-1/10; TR/ABB-VFD Doc rev/IRN end: 16/10; BHEL/Tmeic VFD insp- 28,29/10;Nov: 16 ord (incl.4 FD expediting)+ Insp: TMeic (BHEL S/o)-Drives-8,18/11;Doc Rev/IRN endors: CGL Drives-19/11;Tecnicas/TLT -ID/FD Fans-20/11; Tecnicas/ABB-VFD-13/11; TR - Rev/IRN endors of Exp.Joints & Tube seals(17/12);12ord exp (incl 1 FD sub);Jan:25: 12ord exp (incl 1 FD sub);Feb25: 12 ord (incl 2 FD sub);Mar25:12 ord (incl 2 FD sub; KSBMIL - Rev. & IRN endorsement of 4 lots Control Valves; Apr25: 15ord( inc 2 ord FD sub+1OCS);PO131-rev/end of TPI recds - 4h; May'25: 16ord(incl.1ord FD sub & 1OCS); | J24: Himangshu Pal/Sanjeev Kumar/Ayush Mathur/Shivaji/VVR Murthy | P24: 24h rel. on 5/10;4h rel on 29/2 [56]8h rel on 5/4[64];12h rel on 17/8[90];20h rel on 17/9[110];:16h rel on 10/10[127];18h rel pn 18/11[145]; 30h rel on 26/12[175];20h rel on 10/2[195] ; 35h rel on 21/4[230];15 h rel on 24/5[245]; 15 rel on 16/6[260]
A25: B448 | B25: 1 | C25: 0 | D25: =8*6 | E25: 0 | F25: =SUM(C25:E25) | G25: Insp. & exp. Of Direct ordered items; For LSTK, insp@ payment on manday item rate;resolution of queries on insp from bid till compln. Of pjt;expediting, if reqd. by Owner - Plant Automation tender on ABB - Plant Automation FAT-20-23, 28/5(5.5d); Valves- QAP rev. 15/5(0.5d) | J25: Himangshu Pal/Sanjeev Kumar/UK Mishra/NS Vasudev | Q25: 12 h issued on 11/1;4h rel on 11/3[22];8h rel on 6/4[30];20h rel on 11/5 [50];2h rel on 9/10 (sep ts closed so used in Oct)[56];2h rel on 10/4- to be used in Apr TS[56];18h rel on 22/5[74];4h rel on 1/7[78]; 16h rel on 27/8[110];8h rel on 4/3 [160];32h rel on 21/4[192];60h rel on 8/7[252]
A26: B519 | B26: 3 | C26: =2*B26+1*4 | D26: 0 | E26: 0 | F26: =SUM(C26:E26) | G26: As per Pjt Prof, desk expediting by HO team, unless specifically sought from RPO(critical items). -Insp.(within4 days of call) & FD cert. by us - OCS not applicable. Insp @MIL -PO6823- 22/11; Insp@MIL on 9/12; Mtg. with YIL to expedite Analyser order (being followed up by Client); Mar25: 4 ord expediting - Check OCS status of B519/6821-YIL - shown o/s in Consolidated EPS rept; Apr'25: 2 runn ord (FD exp)+1OCS | J26: Chandrashekhar/HarshVardan/Prakash Jagarwal/DSNMurty
A27: B548 | B27: 0 | C27: 0 | D27: 0 | E27: 0 | F27: =SUM(C27:E27) | G27: Alleima- Exchanger - Exp+QAP comments - ITP R1- rev-6/2; Control Panel ITP rev- 7/2; FAT of TCP rev-12/2; Mtg/communications for resolution of issue w.r.t Heating Element MOC - 6,9/2; Nov: 1 OCS + Insp. - Emerson S/o on Microfinish - 27/11 & 20/12 | J27: HP/Sanjeev Kr/T Ravi/NS Vasudev/Sanjeev Kr Gupta | P27: 8h all on 30/5;4h on 7/8[20];Dec/Jan/Feb-4h each[32];4h rel on 10/4- Mar TS closed- to be used in Apr[36];4h rel on 24/6[40];4h rel on 9/7[44];4h rel on 12/9[48];4h rel on 30/12[52];12h rel on 30/12[64]
A28: B559 | B28: 5 | C28: =2*B28 | D28: 0 | E28: 0 | F28: =SUM(C28:E28) | G28: IOCL Biturox,Vad-Proj. Prof. uploaded on 20/3- Desk Expediting - NO OCS; 4 orders expediting | J28: Sanjay Choudhary/SK Gayen/RK Gupta | P28: 86h rel on 13/3 [86];104h rel on 1/4[190]; 72 sought for Apr- 160 issued considering upcoming Chiller insp (88h extra avl. For May'24[350]-20h rel on 29/5[370];60mh rel on 1/7[386];20mh rel on 1/8[406];16h rel on 25/10[422];1h rel on 24/6 in B559-01[1]
A29: B560 | B29: 13 | C29: =2*B29 | E29: 0 | F29: =SUM(C29:E29) | G29: Req.from ED(I) for expediting on 15/6 - 13 orders (incl.9FD exp & 1 OCS) & OCS also to be made as per latest reqt.; | J29: Chandrashekhar/Vinod Kumar/RK Medhavi | P29: 100h rel on 23/4
A30: B589 | B30: 0 | C30: 0 | D30: 0 | E30: 0 | F30: 0 | J30: Himangshu Pal/Sanjeev Kr/T Ravi/NS Vasudev/Sanjeev Kr Gupta | P30: 8h rel on 6/6;8h on 7/8[18];8in oct,8 in dec,4 in Jan[38];12 on 5/4[50];8h rel on 10/4-Mar TS closed - to be used in Apr.[58];8h rel on 24/6[64];8h rel on 17/8[78];8h rel on 5/9[86];8h rel on 11/9[94]
A31: B650 | B31: 1 | C31: 2 | F31: 0 | G31: No scope for RPO - however, OCS to be done | J31: Sanjay Choudhary/Siddant Kumar
A32: B653 | B32: 14 | C32: =2*B32+1*4 | E32: 8 | F32: =SUM(C32:E32) | G32: Expediting by RPOs as per email dtd 22/10/24, OCS by RPO as per CS mail dt 17/1; (13 running ord+1OCS);Univ Insts -Rev. mtg & Show Cause Notice issue reco. -8h | J32: Sanjeev Kumar/Aasheesh Handa/Amandeep Kaur | P32: 40h rel on 9/4/24 [40]
A33: B725 | B33: 3 | D33: 0 | E33: 0 | F33: =SUM(C33:E33) | G33: No expediting; | J33: Himangshu/Sanjeev Kumar- Scope: Rev. of ITP,Insp Docs & FD | P33: 4h sought by BT on 27/5 to Sanjeev Kr
A34: B767 | D34: 0 | E34: 0 | F34: =SUM(C34:E34) | J34: Himangshu Pal/Vikalp Paliwal/Balakumar | P34: 200 h rel on 8/8/23;20h bkd in Aug; Next tranche of 200h relsd on 10/1/24 (for period Dec to Feb'24)[400];Next tranche of 250h relsd on 9/7/24 (for period Dec'24)[650]-50h rel on 31/3 [700]
A35: B795 | D35: 0 | F35: =SUM(C35:E35) | J35: G Suresh/Patra/Uday Pratap/Rajeev Chak/NS Vasudev | P35: 32h rels. On 12/9;64h on 16/1; addl 100h rel on 20/1 [276]
A36: B813 | B36: 1 | C36: =2*B36 | F36: =SUM(C36:E36) | G36: Expedite & Inspect critical items (list provided in mail dt.29/5/25) EIL on man-day reimbursable basis - 1 order on KSBMIL | J36: Sanjeev Kumar/Raviraj/Shivaji | M36: NRL-Aqueous Ammonia Unit
A37: B862 | G37: manhour for Level- 13 (Group-2), Level -15 & 16 (Group-4) and Level-18 (Group-5) have far exceeded ceiling prescribed in the contract - >Lvl 17-mh limited to 16% | J37: Himangshu Pal/Sanjeev Kumar/Rajeev Khandelwal IOM 10/7/24 from Mr Rajeev Khandelwal on level wise breakup of MH to be booked - to be followed while seeking MH. | M37: PLL | P37: 200h rel in May'25
A38: B865 | G38: EIL-Inspection scope of work is limited to review & approval of QAP and providing dispatch clearance; Moreover, as per contract provision, HPCL may request for inspection by EIL as & when they found it necessary which will be over & above the TPIA inspection and manhours for same shall be reimbursed by HPCL for such shop visits - No expediting at RPO | J38: Avdesh Agrawal | M38: HPCL Petchem Mktg Terminal
A39: B903 | B39: 3 | C39: =2*B39 | F39: =SUM(C39:E39) | J39: Sanjeev Kumar | P39: 10h rel on 2/7[10]
A40: B904 | B40: 1 | C40: =2*1 | F40: =SUM(C40:E40) | J40: Sanjeev Kumar | O40: Proj. prof. n.avl. | P40: 4h rel on 2/7[4]
...

Sheet May25
A1: RPO : Bengaluru | D1: LOCATION CODE : 18-42-506 | H1: MONTH : | I1: 45778 | M1: Total MH reqd: | O1: =ConsolidatedMHrequirementMay25!A2
A3: Job No | B3: Number of Purchase Orders | C3: No of Engineers deployed | D3: No of Inspn / Expediting Visits | E3: No of Expediting Reports / Desk expediting | F3: No of OCRs | G3: Manhours for Inspection | H3: Manhours for expediting | I3: Others | J3: Total Manhours required | K3: Recd as on 25/06/25 | L3: Shortfall
A4: 4994 | B4: =ConsolidatedMHrequirementMay25!B4 | G4: =ConsolidatedMHrequirementMay25!D4 | H4: =ConsolidatedMHrequirementMay25!C4 | I4: =ConsolidatedMHrequirementMay25!E4 | J4: =VLOOKUP(A4,ConsolidatedMHrequirementMay25!$A$4:$I$42,6,FALSE) | K4: 32 | L4: =J4-K4 | M4: =ConsolidatedMHrequirementMay25!G4
A5: 6979 | B5: =ConsolidatedMHrequirementMay25!B5 | G5: =ConsolidatedMHrequirementMay25!D5 | H5: =ConsolidatedMHrequirementMay25!C5 | I5: =ConsolidatedMHrequirementMay25!E5 | J5: =VLOOKUP(A5,ConsolidatedMHrequirementMay25!$A$4:$I$42,6,FALSE) | L5: =J5-K5
A6: 7716 | B6: =ConsolidatedMHrequirementMay25!B6 | G6: =ConsolidatedMHrequirementMay25!D6 | H6: =ConsolidatedMHrequirementMay25!C6 | I6: =ConsolidatedMHrequirementMay25!E6 | J6: =VLOOKUP(A6,ConsolidatedMHrequirementMay25!$A$4:$I$42,6,FALSE) | L6: =J6-K6
A7: 8518 | B7: =ConsolidatedMHrequirementMay25!B7 | G7: =ConsolidatedMHrequirementMay25!D7 | H7: =ConsolidatedMHrequirementMay25!C7 | I7: =ConsolidatedMHrequirementMay25!E7 | J7: =VLOOKUP(A7,ConsolidatedMHrequirementMay25!$A$4:$I$42,6,FALSE) | L7: =J7-K7 | M7: Admin works,Insp Guidelines/Typ Test review/ITP revision(E&I ITPS)/Std. Spec review-mtgs with Inst. Engg. on Cryo Test Procedure & Flow Meter MR improvements,other miscellaneous works incl. Dept Mtg, Office enhancement efforts,Short Term Contracts, New Facility Mgmt Tender requirements freeze etc.,Mktg leads, Hosp Nomination;ITP for Aircooled Exchangers & Wiremesh Demister-12/5,Heat Exch &Columns-13/5+3 ITPs for Vessels/Columns/Reactors (30/5)
A8: 8590 | B8: =ConsolidatedMHrequirementMay25!B8 | G8: =ConsolidatedMHrequirementMay25!D8 | H8: =ConsolidatedMHrequirementMay25!C8 | I8: =ConsolidatedMHrequirementMay25!E8 | J8: =VLOOKUP(A8,ConsolidatedMHrequirementMay25!$A$4:$I$42,6,FALSE) | L8: =J8-K8
A9: B016 | B9: =ConsolidatedMHrequirementMay25!B9 | G9: =ConsolidatedMHrequirementMay25!D9 | H9: =ConsolidatedMHrequirementMay25!C9 | I9: =ConsolidatedMHrequirementMay25!E9 | J9: =VLOOKUP(A9,ConsolidatedMHrequirementMay25!$A$9:$I$42,6,FALSE) | L9: =J9-K9
A10: B035 | B10: =ConsolidatedMHrequirementMay25!B10 | G10: =ConsolidatedMHrequirementMay25!D10 | H10: =ConsolidatedMHrequirementMay25!C10 | I10: =ConsolidatedMHrequirementMay25!E10 | J10: =VLOOKUP(A10,ConsolidatedMHrequirementMay25!$A$9:$I$42,6,FALSE) | L10: =J10-K10 | M10: Expediting - Greensol;
A11: B038 | B11: =ConsolidatedMHrequirementMay25!B11 | G11: =ConsolidatedMHrequirementMay25!D11 | H11: =ConsolidatedMHrequirementMay25!C11 | I11: =ConsolidatedMHrequirementMay25!E11 | J11: =VLOOKUP(A11,ConsolidatedMHrequirementMay25!$A$9:$I$42,6,FALSE) | L11: =J11-K11 | M11: May-1ord FD exp. | V11: pending mh to be filled: | X11: MH avl
A12: B058 | B12: =ConsolidatedMHrequirementMay25!B12 | G12: =ConsolidatedMHrequirementMay25!D12 | H12: =ConsolidatedMHrequirementMay25!C12 | I12: =ConsolidatedMHrequirementMay25!E12 | J12: =VLOOKUP(A12,ConsolidatedMHrequirementMay25!$A$9:$I$42,6,FALSE) | L12: =J12-K12
A13: B224 | B13: =ConsolidatedMHrequirementMay25!B13 | G13: =ConsolidatedMHrequirementMay25!D13 | H13: =ConsolidatedMHrequirementMay25!C13 | I13: =ConsolidatedMHrequirementMay25!E13 | J13: =VLOOKUP(A13,ConsolidatedMHrequirementMay25!$A$9:$I$42,6,FALSE) | L13: =J13-K13 | M13: Tecnip/Micon -insp- 22/5(1d);L&T/YIL-Wireless Insts- 30/5(1d);L&T/YIL Moist Anal Rev/IRN end.- 1/5 (0.5d);JSW-Rev/IRN end of Elec Pkg-6/5 (1d);MEIL-SRU/Cords&KEC QAP rev -8/5(0.5d);Megha/PPU-All elec. Items TPI IRN rev-6/5(1d);Meil-SRU- Mass FM,Mag FM -QAP rev-21/5(1d);Meil/SRU/Nexon Cable QAP rev-27/5(0.5d);MEIL/SRU-PRV QAP-19/5(0.5d);Meil/SRU/Chabi-QAP-27/5(0.5d);
A14: B229 | B14: =ConsolidatedMHrequirementMay25!B14 | G14: =ConsolidatedMHrequirementMay25!D14 | H14: =ConsolidatedMHrequirementMay25!C14 | I14: =ConsolidatedMHrequirementMay25!E14 | J14: =VLOOKUP(A14,ConsolidatedMHrequirementMay25!$A$9:$I$42,6,FALSE) | L14: =J14-K14
A15: B269 | B15: =ConsolidatedMHrequirementMay25!B15 | G15: =ConsolidatedMHrequirementMay25!D15 | H15: =ConsolidatedMHrequirementMay25!C15 | I15: =ConsolidatedMHrequirementMay25!E15 | J15: =VLOOKUP(A15,ConsolidatedMHrequirementMay25!$A$9:$I$42,6,FALSE) | K15: 138 | L15: =J15-K15 | M15: 12 running orders+ 4Orders FD sub expediting+1OCS; Critical Item Insp - YIL- RHCU FAT- 5d (28/4-2/5-(5d); BDK visit- 21-23/5(3d)-posting for expediting rectification/replacement of valves recd.frm site;YIL-1415- RHCU FAT compl- 29/5(1d);Cables Rev/IRN endor - 28/5(0.5d);For Apr+May-38mh rel on 19/6 (against 104+118=222h sought)[1476];Another 100mh rel on 20/6[1576]
A16: B285 | B16: =ConsolidatedMHrequirementMay25!B16 | G16: =ConsolidatedMHrequirementMay25!D16 | H16: =ConsolidatedMHrequirementMay25!C16 | I16: =ConsolidatedMHrequirementMay25!E16 | J16: =VLOOKUP(A16,ConsolidatedMHrequirementMay25!$A$9:$I$42,6,FALSE) | L16: =J16-K16
A17: B297 | B17: =ConsolidatedMHrequirementMay25!B17 | G17: =ConsolidatedMHrequirementMay25!D17 | H17: =ConsolidatedMHrequirementMay25!C17 | I17: =ConsolidatedMHrequirementMay25!E17 | J17: =VLOOKUP(A17,ConsolidatedMHrequirementMay25!$A$9:$I$42,6,FALSE) | L17: =J17-K17 | M17: Exp-6 ord-4 runn ord, 2-FD sub exp; Insp: B297/308 (23/5 - 1d) | V17: Viji | W17: 168
A18: B302 | B18: =ConsolidatedMHrequirementMay25!B18 | G18: =ConsolidatedMHrequirementMay25!D18 | H18: =ConsolidatedMHrequirementMay25!C18 | I18: =ConsolidatedMHrequirementMay25!E18 | J18: =VLOOKUP(A18,ConsolidatedMHrequirementMay25!$A$9:$I$42,6,FALSE) | L18: =J18-K18 | M18: 4 Running orders ; 8731-KEPL/TMEIC-Drives insp- 22-27/5 (5d);2162-KSBMIL-26/5(1d);Shirdi Sai -Online mtg/clarifications
A19: B348 | B19: =ConsolidatedMHrequirementMay25!B19 | G19: =ConsolidatedMHrequirementMay25!D19 | H19: =ConsolidatedMHrequirementMay25!C19 | I19: =ConsolidatedMHrequirementMay25!E19 | J19: =VLOOKUP(A19,ConsolidatedMHrequirementMay25!$A$9:$I$42,6,FALSE) | K19: 0 | L19: =J19-K19 | M19: 13 Running orders +1 ord FD exp+1OCS;22h rel on 4/7/25 for Apr & May [184]
A20: B359 | B20: =ConsolidatedMHrequirementMay25!B20 | G20: =ConsolidatedMHrequirementMay25!D20 | H20: =ConsolidatedMHrequirementMay25!C20 | I20: =ConsolidatedMHrequirementMay25!E20 | J20: =VLOOKUP(A20,ConsolidatedMHrequirementMay25!$A$9:$I$42,6,FALSE) | L20: =J20-K20 | V20: SV | W20: =21*8-4*8 | X20: =90+24+22 | Y20: b035+b436+B767
A21: B378 | B21: =ConsolidatedMHrequirementMay25!B21 | G21: =ConsolidatedMHrequirementMay25!D21 | H21: =ConsolidatedMHrequirementMay25!C21 | I21: =ConsolidatedMHrequirementMay25!E21 | J21: =VLOOKUP(A21,ConsolidatedMHrequirementMay25!$A$9:$I$42,6,FALSE) | K21: 160 | L21: =J21-K21 | M21: 20 ord Expediting(incl 7ord FD sub exp); Inspn: YIL(639-U&O/PP FAT))-2,30/5(2d); (706-Rev/IRN end)-3/5(.5d);ABB(569)-29/5(1d);Schneider -PO 725-7-9,28-30,Rev:26/5 (6.5d);Paramount/C&S-8,9,15,16/5(4d);Mtg. with YIL for resolving o/s Hold-ups in FAT & procurement resply;Meeting/rev. of Cryo Test procedure & expediting of o/s issues; Rev. Mtg. @ YIL alongwith Client -9,15,30/5-(2d); 160h rel on 16/6[4328]
A22: B414 | B22: =ConsolidatedMHrequirementMay25!B22 | G22: =ConsolidatedMHrequirementMay25!D22 | H22: =ConsolidatedMHrequirementMay25!C22 | I22: =ConsolidatedMHrequirementMay25!E22 | J22: =VLOOKUP(A22,ConsolidatedMHrequirementMay25!$A$9:$I$42,6,FALSE) | L22: =J22-K22 | M22: 4 orders ( incl. 3Running orders & 1FD expediting); Insp: Schneider - Sw Bds - B414/55- 7-9,29,Rev:26/5 (4.5d);Pace process/Schneider QAP appls.-27/5(0.5d);
A23: B436 | B23: =ConsolidatedMHrequirementMay25!B23 | G23: =ConsolidatedMHrequirementMay25!D23 | H23: =ConsolidatedMHrequirementMay25!C23 | I23: =ConsolidatedMHrequirementMay25!E23 | J23: =VLOOKUP(A23,ConsolidatedMHrequirementMay25!$A$9:$I$42,6,FALSE) | L23: =J23-K23 | M23: SCADA order on ABB
A24: B440 | B24: =ConsolidatedMHrequirementMay25!B24 | G24: =ConsolidatedMHrequirementMay25!D24 | H24: =ConsolidatedMHrequirementMay25!C24 | I24: 0 | J24: =VLOOKUP(A24,ConsolidatedMHrequirementMay25!$A$9:$I$42,6,FALSE) | K24: 15 | L24: =J24-K24 | M24: May'25: 16ord(incl.1ord FD sub & 1OCS);15h rel on 16/6[260]
A25: B448 | B25: =ConsolidatedMHrequirementMay25!B25 | G25: =ConsolidatedMHrequirementMay25!D25 | H25: =ConsolidatedMHrequirementMay25!C25 | I25: =ConsolidatedMHrequirementMay25!E25 | J25: =VLOOKUP(A25,ConsolidatedMHrequirementMay25!$A$9:$I$42,6,FALSE) | L25: =J25-K25 | M25: Insp. & exp. Of Direct ordered items; For LSTK, insp@ payment on manday item rate;resolution of queries on insp from bid till compln. Of pjt;expediting, if reqd. by Owner - Plant Automation tender on ABB - Plant Automation FAT-20-23, 28/5(5.5d); Valves- QAP rev. 15/5(0.5d) | V25: NV | W25: =168-16 | X25: =30+2 | Y25: b414
A26: B519 | B26: =ConsolidatedMHrequirementMay25!B26 | G26: =ConsolidatedMHrequirementMay25!D26 | H26: =ConsolidatedMHrequirementMay25!C26 | I26: =ConsolidatedMHrequirementMay25!E26 | J26: =VLOOKUP(A26,ConsolidatedMHrequirementMay25!$A$9:$I$42,6,FALSE) | L26: =J26-K26 | M26: 2 runn ord (FD exp)+1OCS | V26: Shortage | W26: =168+152-32
A27: B548 | B27: =ConsolidatedMHrequirementMay25!B27 | G27: =ConsolidatedMHrequirementMay25!D27 | H27: =ConsolidatedMHrequirementMay25!C27 | I27: =ConsolidatedMHrequirementMay25!E27 | J27: =VLOOKUP(A27,ConsolidatedMHrequirementMay25!$A$9:$I$42,6,FALSE) | L27: =J27-K27
A28: B559 | B28: =ConsolidatedMHrequirementMay25!B28 | G28: =ConsolidatedMHrequirementMay25!D28 | H28: =ConsolidatedMHrequirementMay25!C28 | I28: 1 | J28: =VLOOKUP(A28,ConsolidatedMHrequirementMay25!$A$9:$I$42,6,FALSE) | L28: =J28-K28 | M28: IOCL Biturox,Vad-Proj. Prof. uploaded on 20/3- Desk Expediting - NO OCS; 4 orders expediting -1h rel on 24/6 in B559-01[1]
